<sdf version='1.7'>
  <model name='toycar'>

    <link name='base_link'>
      <inertial>
        <pose>0.102528 0.075 0.020089 0 -0 0</pose>
        <mass>0.068</mass>
        <inertia>
          <ixx>0.00208347</ixx>
          <ixy>1.0842e-19</ixy>
          <ixz>5.60189e-05</ixz>
          <iyy>0.00459392</iyy>
          <iyz>-2.71051e-20</iyz>
          <izz>0.0061077</izz>
        </inertia>
      </inertial>
      <collision name='base_link_fixed_joint_lump__body_collision'>
        <pose>0 0 0 0 -0 1.57</pose>
        <geometry>
          <mesh>
            <scale>1 1 1</scale>
            <uri>file:///home/pablo/Projects/2d_DDR/install/gz_ignition/share/gz_ignition/models/robot_models/toycar/meshes/low_part.stl</uri>
          </mesh>
        </geometry>
        <surface>
          <contact>
            <ode/>
          </contact>
          <friction>
            <ode/>
          </friction>
        </surface>
      </collision>
      <collision name='base_link_fixed_joint_lump__caster_collision_1'>
        <pose>0.2 0.075 -0.01 0 -0 3.14159</pose>
        <geometry>
          <mesh>
            <scale>1 1 1</scale>
            <uri>file:///home/pablo/Projects/2d_DDR/install/gz_ignition/share/gz_ignition/models/robot_models/toycar/meshes/caster.stl</uri>
          </mesh>
        </geometry>
        <surface>
          <contact>
            <ode/>
          </contact>
          <friction>
            <ode/>
          </friction>
        </surface>
      </collision>

      <visual name='base_link_fixed_joint_lump__body_visual'>
        <pose>0 0 0 0 -0 1.57</pose>
        <geometry>
          <mesh>
            <scale>1 1 1</scale>
            <uri>file:///home/pablo/Projects/2d_DDR/install/gz_ignition/share/gz_ignition/models/robot_models/toycar/meshes/low_part.stl</uri>
          </mesh>
        </geometry>
        <material>
          <script>
            <name>Gazebo/White</name>
            <uri>file://media/materials/scripts/gazebo.material</uri>
          </script>
        </material>
      </visual>
      <visual name='base_link_fixed_joint_lump__caster_visual_1'>
        <pose>0.2 0.075 -0.01 0 -0 3.14159</pose>
        <geometry>
          <mesh>
            <scale>1 1 1</scale>
            <uri>file:///home/pablo/Projects/2d_DDR/install/gz_ignition/share/gz_ignition/models/robot_models/toycar/meshes/caster.stl</uri>
          </mesh>
        </geometry>
      </visual>

      <sensor name='camera_L' type='camera'>
        <update_rate>30</update_rate>
        <visualize>1</visualize>
        <camera name='head'>
          <horizontal_fov>1.39626</horizontal_fov>
          <image>
            <width>800</width>
            <height>800</height>
            <format>R8G8B8</format>
          </image>
          <clip>
            <near>0.02</near>
            <far>300</far>
          </clip>
          <noise>
            <type>gaussian</type>
            <mean>0</mean>
            <stddev>0</stddev>
          </noise>
        </camera>
        <plugin name='camera_L' filename='libgazebo_ros_camera.so'>
          <ros>
            <namespace>camera_L</namespace>
            <remapping>~/image_raw:=color_raw_L</remapping>
            <remapping>~/depth/image_raw:=depth/image_rect_raw</remapping>
            <remapping>~/camera_info:=camera_info</remapping>
            <remapping>~/depth/camera_info:=depth/camera_info</remapping>
            <remapping>~/points:=depth/points</remapping>
          </ros>
          <alwaysOn>1</alwaysOn>
          <updateRate>30.0</updateRate>
          <cameraName>toycar/camera_L</cameraName>
          <frameName>camera_L</frameName>
          <hackBaseline>0.07</hackBaseline>
          <distortionK1>0.0</distortionK1>
          <distortionK2>0.0</distortionK2>
          <distortionK3>0.0</distortionK3>
          <distortionT1>0.0</distortionT1>
          <distortionT2>0.0</distortionT2>
          <min_depth>0.05</min_depth>
          <max_depth>8.0</max_depth>
        </plugin>
        <pose>0.25 0.076 0.03 0 -0 0</pose>
      </sensor>
      <sensor name='camera_R' type='camera'>
        <update_rate>30</update_rate>
        <visualize>1</visualize>
        <camera name='head'>
          <horizontal_fov>1.39626</horizontal_fov>
          <image>
            <width>800</width>
            <height>800</height>
            <format>R8G8B8</format>
          </image>
          <clip>
            <near>0.02</near>
            <far>300</far>
          </clip>
          <noise>
            <type>gaussian</type>
            <mean>0</mean>
            <stddev>0</stddev>
          </noise>
        </camera>
        <plugin name='camera_R_controller' filename='libgazebo_ros_camera.so'>
          <alwaysOn>1</alwaysOn>
          <updateRate>0.0</updateRate>
          <cameraName>toycar/camera_R</cameraName>
          <frameName>camera_R</frameName>
          <hackBaseline>0.07</hackBaseline>
          <distortionK1>0.0</distortionK1>
          <distortionK2>0.0</distortionK2>
          <distortionK3>0.0</distortionK3>
          <distortionT1>0.0</distortionT1>
          <distortionT2>0.0</distortionT2>
        </plugin>
        <pose>0.25 0.074 0.03 0 -0 0</pose>
      </sensor>
      <gravity>1</gravity>

      <sensor name='ray' type='ray'>
        <visualize>1</visualize>
        <update_rate>1</update_rate>
        <ray>
          <scan>
            <horizontal>
              <samples>150</samples>
              <min_angle>-1</min_angle>
              <max_angle>1</max_angle>
              <resolution>1</resolution>
            </horizontal>
          </scan>
          <range>
            <min>0.3</min>
            <max>15</max>
            <resolution>0.01</resolution>
          </range>
        </ray>
        <plugin name='laser_scan' filename='libgazebo_ros_ray_sensor.so'>
          <ros>
            <remapping>~/out:=laser_scan</remapping>
          </ros>
          <output_type>sensor_msgs/LaserScan</output_type>
          <frameName>laser_frame</frameName>
        </plugin>
        <pose>0.2 0.1 0.1 0 -0 0</pose>
      </sensor>


      <sensor name='gpu_lidar' type='gpu_lidar'>
        <topic>lidar</topic>
        <update_rate>10</update_rate>
        <lidar>
          <scan>
            <horizontal>
              <samples>640</samples>
              <resolution>1</resolution>
              <min_angle>-1.396263</min_angle>
              <max_angle>1.396263</max_angle>
            </horizontal>
            <vertical>
              <samples>16</samples>
              <resolution>1</resolution>
              <min_angle>-0.261799</min_angle>
              <max_angle>0.261799</max_angle>
            </vertical>
          </scan>
          <range>
            <min>0.08</min>
            <max>10.0</max>
            <resolution>0.01</resolution>
          </range>
        </lidar>
        <alwaysOn>1</alwaysOn>
        <visualize>true</visualize>
      </sensor>

    </link>
    
    <joint name='joint_wheel_L' type='revolute'>
      <pose relative_to='base_link'>0.05 0.156 0.015 0 -0 0</pose>
      <parent>base_link</parent>
      <child>wheel_L</child>
      <axis>
        <xyz>0 1 0</xyz>
        <limit>
          <lower>-1e+16</lower>
          <upper>1e+16</upper>
        </limit>
        <dynamics>
          <spring_reference>0</spring_reference>
          <spring_stiffness>0</spring_stiffness>
        </dynamics>
      </axis>
    </joint>
    <link name='wheel_L'>
      <pose relative_to='joint_wheel_L'>0 0 0 0 -0 0</pose>
      <inertial>
        <pose>0 0 0 1.57 -0 0</pose>
        <mass>0.016</mass>
        <inertia>
          <ixx>5.857e-06</ixx>
          <ixy>0</ixy>
          <ixz>0</ixz>
          <iyy>1.1633e-05</iyy>
          <iyz>0</iyz>
          <izz>5.857e-06</izz>
        </inertia>
      </inertial>
      <collision name='wheel_L_collision'>
        <pose>0 0 0 0 -0 0</pose>
        <geometry>
          <mesh>
            <scale>1 1 1</scale>
            <uri>file:///home/pablo/Projects/2d_DDR/install/gz_ignition/share/gz_ignition/models/robot_models/toycar/meshes/wheel.stl</uri>
          </mesh>
        </geometry>
        <surface>
          <contact>
            <ode>
              <kp>1e+07</kp>
              <kd>1</kd>
            </ode>
          </contact>
          <friction>
            <ode>
              <mu>3</mu>
              <mu2>4</mu2>
              <fdir1>1 0 0</fdir1>
            </ode>
          </friction>
        </surface>
      </collision>
      <visual name='wheel_L_visual'>
        <pose>0 0 0 0 -0 0</pose>
        <geometry>
          <mesh>
            <scale>1 1 1</scale>
            <uri>file:///home/pablo/Projects/2d_DDR/install/gz_ignition/share/gz_ignition/models/robot_models/toycar/meshes/wheel.stl</uri>
          </mesh>
        </geometry>
        <material>
          <script>
            <name>Gazebo/Grey</name>
            <uri>file://media/materials/scripts/gazebo.material</uri>
          </script>
        </material>
      </visual>
      <gravity>1</gravity>
    </link>

    <joint name='joint_wheel_R' type='revolute'>
      <pose relative_to='base_link'>0.05 -0.006 0.015 0 -0 0</pose>
      <parent>base_link</parent>
      <child>wheel_R</child>
      <axis>
        <xyz>0 1 0</xyz>
        <limit>
          <lower>-1e+16</lower>
          <upper>1e+16</upper>
        </limit>
        <dynamics>
          <spring_reference>0</spring_reference>
          <spring_stiffness>0</spring_stiffness>
        </dynamics>
      </axis>
    </joint>
    <link name='wheel_R'>
      <pose relative_to='joint_wheel_R'>0 0 0 0 -0 0</pose>
      <inertial>
        <pose>0 0 0 1.57 -0 0</pose>
        <mass>0.016</mass>
        <inertia>
          <ixx>5.857e-06</ixx>
          <ixy>0</ixy>
          <ixz>0</ixz>
          <iyy>1.1633e-05</iyy>
          <iyz>0</iyz>
          <izz>5.857e-06</izz>
        </inertia>
      </inertial>
      <collision name='wheel_R_collision'>
        <pose>0 0 0 0 -0 0</pose>
        <geometry>
          <mesh>
            <scale>1 1 1</scale>
            <uri>file:///home/pablo/Projects/2d_DDR/install/gz_ignition/share/gz_ignition/models/robot_models/toycar/meshes/wheel.stl</uri>
          </mesh>
        </geometry>
        <surface>
          <contact>
            <ode>
              <kp>1e+07</kp>
              <kd>1</kd>
            </ode>
          </contact>
          <friction>
            <ode>
              <mu>1</mu>
              <mu2>1</mu2>
              <fdir1>1 0 0</fdir1>
            </ode>
          </friction>
        </surface>
      </collision>
      <visual name='wheel_R_visual'>
        <pose>0 0 0 0 -0 0</pose>
        <geometry>
          <mesh>
            <scale>1 1 1</scale>
            <uri>file:///home/pablo/Projects/2d_DDR/install/gz_ignition/share/gz_ignition/models/robot_models/toycar/meshes/wheel.stl</uri>
          </mesh>
        </geometry>
        <material>
          <script>
            <name>Gazebo/Grey</name>
            <uri>file://media/materials/scripts/gazebo.material</uri>
          </script>
        </material>
      </visual>
      <gravity>1</gravity>
    </link>

    <plugin name='libgazebo_ros_p3d' filename='libgazebo_ros_p3d.so'>
      <topicName>body_pose_ground_truth</topicName>
      <frame_name>map</frame_name>
      <body_name>base_link</body_name>
      <update_rate>200.0</update_rate>
      <gaussian_noise>0.01</gaussian_noise>
    </plugin>

    <plugin name='differential_drive_controller' filename='libgazebo_ros_diff_drive.so'>
      <update_rate>10</update_rate>
      <left_joint>joint_wheel_L</left_joint>
      <right_joint>joint_wheel_R</right_joint>
      <wheel_separation>0.142</wheel_separation>
      <wheel_diameter>0.045</wheel_diameter>
      <wheelAcceleration>0.8</wheelAcceleration>
      <wheelTorque>10</wheelTorque>
      <odometry_frame>odom_diff_drive</odometry_frame>
      <robotBaseFrame>base_footprint</robotBaseFrame>
      <odometrySource>1</odometrySource>
      <publishWheelTF>1</publishWheelTF>
      <publishOdom>1</publishOdom>
      <publish_odom>1</publish_odom>
      <publishWheelJointState>1</publishWheelJointState>
      <legacyMode>0</legacyMode>
      <max_wheel_torque>200</max_wheel_torque>
      <max_acceleration>3.0</max_acceleration>
    </plugin>

    <plugin
      filename="gz-sim-diff-drive-system"
      name="gz::sim::systems::DiffDrive">
      <left_joint>joint_wheel_L</left_joint>
      <right_joint>joint_wheel_R</right_joint>
      <wheel_separation>0.142</wheel_separation>
      <wheel_radius>0.045</wheel_radius>
      <odom_publish_frequency>1</odom_publish_frequency>
      <max_linear_acceleration>1</max_linear_acceleration>
      <min_linear_acceleration>-1</min_linear_acceleration>
      <max_angular_acceleration>2</max_angular_acceleration>
      <min_angular_acceleration>-2</min_angular_acceleration>
      <max_linear_velocity>0.5</max_linear_velocity>
      <min_linear_velocity>-0.5</min_linear_velocity>
      <max_angular_velocity>1</max_angular_velocity>
      <min_angular_velocity>-1</min_angular_velocity>
    </plugin>

    <static>0</static>

    <plugin name='gazebo_ros_joint_state_publisher' filename='libgazebo_ros_joint_state_publisher.so'>
      <update_rate>20</update_rate>
      <joint_name>joint_wheel_L</joint_name>
      <joint_name>joint_wheel_R</joint_name>
    </plugin>
  </model>
</sdf>
