<?xml version="1.0"?>
<robot xmlns:xacro="http://www.ros.org/wiki/xacro"  name="toycar">

    <material name="black">
        <color rgba="0.0 0.0 0.0 1.0"/>
    </material>
    <material name="white">
        <color rgba="1.0 1.0 1.0 1.0"/>
    </material>
    <material name="blue">
        <color rgba="0 0 0.8 1"/>
    </material>

    <!--LINKS for the geometry of the robot-->
    <link name="base_link"></link>

    <link name="body">
        <inertial>
            <origin xyz="0.074941 0.075 0.028605" rpy="0.0 0.0 0.0"/>
            <mass value="0.0530"/>
            <inertia ixx="0.0020647" ixy="0.0" ixz="-0.000000425" iyy="0.0043923" iyz="0.0" izz="0.0059235"/>
        </inertial>
        <visual>
            <origin xyz="0.0 0.0 0.0" rpy="0.0 0.0 1.57"/>
            <geometry>
                <mesh filename="file://$(find apartment_sim)/robot_models/toycar/meshes/low_part.stl" scale="1 1 1"/>
            </geometry>
            <material name="">
                <color
                    rgba="1.0 1.0 1.0 1" />
            </material>
        </visual>
        <collision>
            <origin xyz="0.0 0.0 0.0" rpy="0.0 0.0 1.57"/>
            <geometry>
                <mesh filename="file://$(find apartment_sim)/robot_models/toycar/meshes/low_part.stl" scale="1 1 1"/>
            </geometry>
        </collision>
    </link>
    
    <link name="wheel_L">
        <inertial>
            <origin xyz="0.0 0.0 0.0" rpy="1.57 0.0 0.0"/>
            <mass value="0.016"/>
            <inertia ixx="0.000005857" ixy="0.0" ixz="0.0" iyy="0.000011633" iyz="0.0" izz="0.000005857"/>
        </inertial>
        <visual>
            <origin xyz="0.0 0.0 0.0" rpy="0 0.0 0.0"/>
            <geometry>
                <mesh filename="file://$(find apartment_sim)/robot_models/toycar/meshes/wheel.stl" scale="1 1 1" />
            </geometry>
            <material name="blue"/>
        </visual>
        <collision>
            <origin xyz="0.0 0.0 0.0" rpy="0 0.0 0.0"/>
            <geometry>
                <mesh filename="file://$(find apartment_sim)/robot_models/toycar/meshes/wheel.stl" scale="1 1 1" />
            </geometry>
        </collision>
    </link>

    <link name="wheel_R">
        <inertial>
            <origin xyz="0.0 0.0 0.0" rpy="1.57 0.0 0.0"/>
            <mass value="0.016"/>
            <inertia ixx="0.000005857" ixy="0.0" ixz="0.0" iyy="0.000011633" iyz="0.0" izz="0.000005857"/>
        </inertial>
        <visual>
            <origin xyz="0.0 0.0 0.0" rpy="0 0.0 0.0"/>
            <geometry>
                <mesh filename="file://$(find apartment_sim)/robot_models/toycar/meshes/wheel.stl" scale="1 1 1" />
            </geometry>
            <material name="blue"/>
        </visual>
        <collision>
            <origin xyz="0.0 0.0 0.0" rpy="0 0.0 0.0"/>
            <geometry>
                <mesh filename="file://$(find apartment_sim)/robot_models/toycar/meshes/wheel.stl" scale="1 1 1" />
            </geometry>
        </collision>
    </link>
    
    <link name="caster">
        <inertial>
            <origin xyz="0.0 0.0 0.0" rpy="0.0 0.0 0.0"/>
            <mass value="0.015"/>
            <inertia ixx="0.000001349" ixy="0.0" ixz="0.0" iyy="0.000001349" iyz="0.0" izz="0.000001349"/>
        </inertial>
        <visual>
            <origin xyz="0.0 0.0 0.0" rpy="0 0.0 0.0"/>
            <geometry>
                <mesh filename="file://$(find apartment_sim)/robot_models/toycar/meshes/caster.stl" scale="1 1 1" />
            </geometry>
            <material name="black"/>
        </visual>
        <collision>
            <origin xyz="0.0 0.0 0.0" rpy="0 0.0 0.0"/>
            <geometry>
                <mesh filename="file://$(find apartment_sim)/robot_models/toycar/meshes/caster.stl" scale="1 1 1" />
            </geometry>
        </collision>
    </link>
    

    <!--JOINTS for the geometry of the robot-->
    <joint name="joint_body" type="fixed">
        <parent link="base_link"/>
        <child link="body"/>
        <origin xyz="0.0 0.0 0.0" rpy="0.0 0.0 0.0"/>
    </joint>

    <joint name="joint_wheel_L" type="continuous">
        <parent link="body"/>
        <child link="wheel_L"/>
        <origin xyz="0.05 0.156 0.015" rpy="0.0 0.0 0.0"/>
        <axis xyz="0.0 1.0 0.0"/>
    </joint>


    <joint name="joint_wheel_R" type="continuous">
        <parent link="body"/>
        <child link="wheel_R"/>
        <origin xyz="0.05 -0.006 0.015" rpy="0.0 0.0 0.0"/>
        <axis xyz="0.0 1.0 0.0"/>
    </joint>

    <joint name="joint_caster" type="fixed">
        <parent link="body"/>
        <child link="caster"/>
        <origin xyz="0.2 0.075 -0.01" rpy="0.0 0.0 3.141592"/>
    </joint>

    <!-- RAYS SCANNER -->
    <xacro:include filename="$(find apartment_sim)/robot_models/toycar/sensors/ray_scanner.xacro"/>

    <!-- Cameras -->
    <!-- <xacro:include filename="$(find apartment_sim)/robot_models/toycar/sensors/camera_R.xacro"/>
    <xacro:include filename="$(find apartment_sim)/robot_models/toycar/sensors/camera_L.xacro"/> -->

    <!-- POSE AND LOCALIZATION -->
    <xacro:include filename="$(find apartment_sim)/robot_models/toycar/sensors/p3d.xacro"/>

    <!-- DIFFERENTIAL DRIVE -->
    <xacro:include filename="$(find apartment_sim)/robot_models/toycar/desc/diff_drive.xacro"/>

    <!-- JOINT STATE PUBLISHER -->
    <xacro:include filename="$(find apartment_sim)/robot_models/toycar/desc/joint_state.xacro"/>

    <!-- GAZEBO VALUES -->
    <xacro:include filename="$(find apartment_sim)/robot_models/toycar/desc/gazebo.xacro"/>

</robot>