<?xml version="1.0" ?>
<!-- =================================================================================== -->
<!-- |    This document was autogenerated by xacro from src/apartment_sim/robot_models/toycar/desc/toycar.xacro | -->
<!-- |    EDITING THIS FILE BY HAND IS NOT RECOMMENDED                                 | -->
<!-- =================================================================================== -->
<robot name="toycar">
  <!--LINKS-->
  <link name="base_link"></link>
  <link name="body">
    <inertial>
      <origin rpy="0.0 0.0 0.0" xyz="0.074941 0.075 0.028605"/>
      <mass value="0.0530"/>
      <inertia ixx="0.0020647" ixy="0.0" ixz="-0.000000425" iyy="0.0043923" iyz="0.0" izz="0.0059235"/>
    </inertial>
    <visual>
      <origin rpy="0.0 0.0 1.57" xyz="0.0 0.0 0.0"/>
      <geometry>
        <mesh filename="/home/pablo/Projects/ROS/2d_DDR/install/apartment_sim/share/apartment_sim/robot_models/toycar/meshes/low_part.stl" scale="1 1 1"/>
      </geometry>
    </visual>
    <collision>
      <origin rpy="0.0 0.0 1.57" xyz="0.0 0.0 0.0"/>
      <geometry>
        <mesh filename="/home/pablo/Projects/ROS/2d_DDR/install/apartment_sim/share/apartment_sim/robot_models/toycar/meshes/low_part.stl" scale="1 1 1"/>
      </geometry>
    </collision>
  </link>
  <link name="wheel_L">
    <inertial>
      <origin rpy="1.57 0.0 0.0" xyz="0.0 0.0 0.0"/>
      <mass value="0.016"/>
      <inertia ixx="0.000005857" ixy="0.0" ixz="0.0" iyy="0.000011633" iyz="0.0" izz="0.000005857"/>
    </inertial>
    <visual>
      <origin rpy="0 0.0 0.0" xyz="0.0 0.0 0.0"/>
      <geometry>
        <mesh filename="/home/pablo/Projects/ROS/2d_DDR/install/apartment_sim/share/apartment_sim/robot_models/toycar/meshes/wheel.stl" scale="1 1 1"/>
      </geometry>
    </visual>
    <collision>
      <origin rpy="0 0.0 0.0" xyz="0.0 0.0 0.0"/>
      <geometry>
        <mesh filename="/home/pablo/Projects/ROS/2d_DDR/install/apartment_sim/share/apartment_sim/robot_models/toycar/meshes/wheel.stl" scale="1 1 1"/>
      </geometry>
    </collision>
  </link>
  <link name="wheel_R">
    <inertial>
      <origin rpy="1.57 0.0 0.0" xyz="0.0 0.0 0.0"/>
      <mass value="0.016"/>
      <inertia ixx="0.000005857" ixy="0.0" ixz="0.0" iyy="0.000011633" iyz="0.0" izz="0.000005857"/>
    </inertial>
    <visual>
      <origin rpy="0 0.0 0.0" xyz="0.0 0.0 0.0"/>
      <geometry>
        <mesh filename="/home/pablo/Projects/ROS/2d_DDR/install/apartment_sim/share/apartment_sim/robot_models/toycar/meshes/wheel.stl" scale="1 1 1"/>
      </geometry>
    </visual>
    <collision>
      <origin rpy="0 0.0 0.0" xyz="0.0 0.0 0.0"/>
      <geometry>
        <mesh filename="/home/pablo/Projects/ROS/2d_DDR/install/apartment_sim/share/apartment_sim/robot_models/toycar/meshes/wheel.stl" scale="1 1 1"/>
      </geometry>
    </collision>
  </link>
  <link name="caster">
    <inertial>
      <origin rpy="0.0 0.0 0.0" xyz="0.0 0.0 0.0"/>
      <mass value="0.015"/>
      <inertia ixx="0.000001349" ixy="0.0" ixz="0.0" iyy="0.000001349" iyz="0.0" izz="0.000001349"/>
    </inertial>
    <visual>
      <origin rpy="0 0.0 0.0" xyz="0.0 0.0 0.0"/>
      <geometry>
        <mesh filename="/home/pablo/Projects/ROS/2d_DDR/install/apartment_sim/share/apartment_sim/robot_models/toycar/meshes/caster.stl" scale="1 1 1"/>
      </geometry>
    </visual>
    <collision>
      <origin rpy="0 0.0 0.0" xyz="0.0 0.0 0.0"/>
      <geometry>
        <mesh filename="/home/pablo/Projects/ROS/2d_DDR/install/apartment_sim/share/apartment_sim/robot_models/toycar/meshes/caster.stl" scale="1 1 1"/>
      </geometry>
    </collision>
  </link>
  <!--JOINTS-->
  <joint name="joint_wheel_L" type="continuous">
    <parent link="body"/>
    <child link="wheel_L"/>
    <origin rpy="0.0 0.0 0.0" xyz="0.05 0.156 0.015"/>
    <axis xyz="0.0 1.0 0.0"/>
  </joint>
  <joint name="joint_wheel_R" type="continuous">
    <parent link="body"/>
    <child link="wheel_R"/>
    <origin rpy="0.0 0.0 0.0" xyz="0.05 -0.006 0.015"/>
    <axis xyz="0.0 1.0 0.0"/>
  </joint>
  <joint name="joint_caster" type="fixed">
    <parent link="body"/>
    <child link="caster"/>
    <origin rpy="0.0 0.0 3.141592" xyz="0.2 0.075 -0.01"/>
  </joint>
  <gazebo reference="laz_base">
    <material>Gazebo/Grey</material>
    <mu1>0.2</mu1>
    <mu2>0.2</mu2>
  </gazebo>
  <link name="laz_base">
    <visual>
      <geometry>
        <cylinder length="0.005" radius="0.005"/>
      </geometry>
    </visual>
    <collision>
      <geometry>
        <cylinder length="0.005" radius="0.005"/>
      </geometry>
    </collision>
    <inertial>
      <mass value="0.001"/>
      <inertia ixx="8.333333333333332e-09" ixy="0" ixz="0" iyy="8.333333333333332e-09" iyz="0" izz="1.2500000000000001e-08"/>
    </inertial>
  </link>
  <link name="laz_rot">
    <visual>
      <geometry>
        <cylinder length="0.01" radius="0.004"/>
      </geometry>
    </visual>
    <collision>
      <geometry>
        <cylinder length="0.01" radius="0.004"/>
      </geometry>
    </collision>
    <inertial>
      <mass value="0.001"/>
      <inertia ixx="1.2333333333333335e-08" ixy="0" ixz="0" iyy="1.2333333333333335e-08" iyz="0" izz="8e-09"/>
    </inertial>
  </link>
  <joint name="joint_rotational_2d_lidar" type="continuous">
    <parent link="laz_base"/>
    <child link="laz_rot"/>
    <axis xyz="0 0 1"/>
    <origin rpy="0.0 0.0 0.0" xyz="0 0 0.0025"/>
    <dynamics friction="0.1"/>
  </joint>
  <joint name="joint_2d_lidar" type="fixed">
    <parent link="body"/>
    <child link="laz_base"/>
    <origin rpy="0.0 0.0 0.0" xyz="0.25 0.075 0.028605"/>
  </joint>
  <gazebo reference="laz_rot">
    <material>Gazebo/RedGlow</material>
    <mu1>0.2</mu1>
    <mu2>0.2</mu2>
    <sensor name="laz" type="ray">
      <pose>0.004 0 0.0025 0 0 0</pose>
      <always_on>true</always_on>
      <visualize>true</visualize>
      <update_rate>10</update_rate>
      <ray>
        <scan>
          <horizontal>
            <samples>100</samples>
            <resolution>1</resolution>
            <min_angle>-0.39269908169872414</min_angle>
            <max_angle>0.39269908169872414</max_angle>
          </horizontal>
          <vertical>
            <samples>1</samples>
            <resolution>1</resolution>
            <min_angle>0</min_angle>
            <max_angle>0</max_angle>
          </vertical>
        </scan>
        <range>
          <min>0.05</min>
          <max>15</max>
          <resolution>0.02</resolution>
        </range>
      </ray>
      <plugin filename="libgazebo_ros_ray_sensor.so" name="scan">
        <output_type>sensor_msgs/LaserScan</output_type>
        <topicName>/laser/scan</topicName>
        <frameName>laz_rot</frameName>
      </plugin>
    </sensor>
  </gazebo>
</robot>
