<?xml version="1.0"?>
<robot xmlns:xacro="http://www.ros.org/wiki/xacro"  name="robot">

    <!-- <xacro:include filename="$(find toycar)/urdf/ray_scanner.xacro"/> -->
    <xacro:include filename="$(find toycar)/urdf/ray_scanner.xacro"/>

    <!--LINKS-->
    <!-- <link name="base_link"></link> -->

    <link name="body">
        <inertial>
            <origin xyz="0.074941 0.075 0.028605" rpy="0.0 0.0 0.0"/>
            <mass value="0.0530"/>
            <inertia ixx="0.0020647" ixy="0.0" ixz="-0.000000425" iyy="0.0043923" iyz="0.0" izz="0.0059235"/>
        </inertial>
        <visual>
            <origin xyz="0.0 0.0 0.0" rpy="0.0 0.0 1.57"/>
            <geometry>
                <mesh filename="$(find toycar)/meshes/low_part.stl" scale="1 1 1"/>
            </geometry>
        </visual>
        <collision>
            <origin xyz="0.0 0.0 0.0" rpy="0.0 0.0 1.57"/>
            <geometry>
                <mesh filename="$(find toycar)/meshes/low_part.stl" scale="1 1 1"/>
            </geometry>
        </collision>
    </link>
    
    <link name="wheel_L">
        <inertial>
            <origin xyz="0.0 0.0 0.0" rpy="1.57 0.0 0.0"/>
            <mass value="0.016"/>
            <inertia ixx="0.000005857" ixy="0.0" ixz="0.0" iyy="0.000011633" iyz="0.0" izz="0.000005857"/>
        </inertial>
        <visual>
            <origin xyz="0.0 0.0 0.0" rpy="0 0.0 0.0"/>
            <geometry>
                <mesh filename="$(find toycar)/meshes/wheel.stl" scale="1 1 1" />
            </geometry>
        </visual>
        <collision>
            <origin xyz="0.0 0.0 0.0" rpy="0 0.0 0.0"/>
            <geometry>
                <mesh filename="$(find toycar)/meshes/wheel.stl" scale="1 1 1" />
            </geometry>
        </collision>
    </link>

    <link name="wheel_R">
        <inertial>
            <origin xyz="0.0 0.0 0.0" rpy="1.57 0.0 0.0"/>
            <mass value="0.016"/>
            <inertia ixx="0.000005857" ixy="0.0" ixz="0.0" iyy="0.000011633" iyz="0.0" izz="0.000005857"/>
        </inertial>
        <visual>
            <origin xyz="0.0 0.0 0.0" rpy="0 0.0 0.0"/>
            <geometry>
                <mesh filename="$(find toycar)/meshes/wheel.stl" scale="1 1 1" />
            </geometry>
        </visual>
        <collision>
            <origin xyz="0.0 0.0 0.0" rpy="0 0.0 0.0"/>
            <geometry>
                <mesh filename="$(find toycar)/meshes/wheel.stl" scale="1 1 1" />
            </geometry>
        </collision>
    </link>
    
    <link name="caster">
        <inertial>
            <origin xyz="0.0 0.0 0.0" rpy="0.0 0.0 0.0"/>
            <mass value="0.015"/>
            <inertia ixx="0.000001349" ixy="0.0" ixz="0.0" iyy="0.000001349" iyz="0.0" izz="0.000001349"/>
        </inertial>
        <visual>
            <origin xyz="0.0 0.0 0.0" rpy="0 0.0 0.0"/>
            <geometry>
                <mesh filename="$(find toycar)/meshes/caster.stl" scale="1 1 1" />
            </geometry>
        </visual>
        <collision>
            <origin xyz="0.0 0.0 0.0" rpy="0 0.0 0.0"/>
            <geometry>
                <mesh filename="$(find toycar)/meshes/caster.stl" scale="1 1 1" />
            </geometry>
        </collision>
    </link>

    <!--JOINTS-->

    <joint name="joint_wheel_L" type="continuous">
        <parent link="body"/>
        <child link="wheel_L"/>
        <origin xyz="0.05 0.156 0.015" rpy="0.0 0.0 0.0"/>
        <axis xyz="0.0 1.0 0.0"/>
    </joint>

    <joint name="joint_wheel_R" type="continuous">
        <parent link="body"/>
        <child link="wheel_R"/>
        <origin xyz="0.05 -0.006 0.015" rpy="0.0 0.0 0.0"/>
        <axis xyz="0.0 1.0 0.0"/>
    </joint>

    <joint name="joint_caster" type="fixed">
        <parent link="body"/>
        <child link="caster"/>
        <origin xyz="0.2 0.075 -0.01" rpy="0.0 0.0 3.141592"/>
    </joint>

    <xacro:include filename="cameras.xacro"/>
    <xacro:include filename="pose.xacro"/>
    <xacro:include filename="differential_drive.xacro"/>
    <xacro:include filename="joints_control.xacro"/>

</robot>